Workbook
Name Reponse: 'Parameters '!$B$4:$B$5
Name RHInternes: #REF!
Name RHInternes: #REF!
Name RHInternes: #REF!

Sheet Parameters 
A1: Enter the % of applicable tax here | B1: 0.056879 | C1: =B1+1 -> 1.056879
A2: Enter here the % increase in annual recurrence | B2: 0.05 | C2: =B2+1 -> 1.05
A3: First year of the project | B3: 2023-2024
A4: Choice of Answer (O)ui, (N)on: | B4: O
B5: N
A6: Choice of Answer (I)mmo, (E)xpl: | B6: I
B7: E
A9: INFORMATION TAXES | D9: A place to keep other rates
A10: Rate applicable | B10: 0.056879
A11: Rate applicable if Youth Centre only
A12: Rate inverse | B12: 0.9462

Sheet Budget Execution
S1: Catégorie de coûts | T1: Source de financement
A2: Project Name: | B2: Test | S2: Acquisition | T2: Budget de fonctionnement - Courant (CAP)
A3: Project #: | B3: 1021995 | S3: Autres frais | T3: Budget de fonctionnement - Solde de fonds (CAP)
A4: Project Manager: | B4: Mr. Pramod | S4: Impartition auprès d'un autre OP | T4: Budget de fonctionnement - Crédits reportés (CAP)
A5: Account Number: | B5: 9300867-70560 | S5: Location | T5: Budget de fonctionnement - Solde de fonds (NON CAP)
S6: Rémunération du personnel de l'OP | T6: Budget de fonctionnement - Crédits reportés (NON CAP)
A7: Execution | S7: Rémunération du personnel d'un autre OP en PS | T7: Budget d'immobilisation - Courant (CAP)
A8: Description | B8: Cost category | C8: Add tax (Y/N) | D8: Supplier | E8: G/L Account | F8: Source of Financing | G8: 2023-2024 | I8: 2024-2025 | K8: 2025-2026 | M8: 2026-2027 | O8: 2027-2028 | Q8: Comments | S8: Réserve | T8: Budget d'immobilisation - Solde de fonds (CAP)
G9: Cost before tax | H9: Tax Included | I9: Cost before tax | J9: Tax Included | K9: Cost before tax | L9: Tax Included | M9: Cost before tax | N9: Tax Included | O9: Cost before tax | P9: Tax Included | S9: Ressources externes | T9: Budget d'immobilisation - Crédits reportés (CAP)
A10: Operating fund expenditures | T10: Autres dépenses TI de nature captalisable (ADTI)
A11: Project management | B11: Rémunération du personnel d'un autre OP en PS | C11: O | F11: Autres - Transfert MSSS - Non Cap | G11: 350 | H11: =IF($C11="O",ROUND(ROUND(G11,2)*'Parameters '!$C$1,2),ROUND(G11,2)) -> 369.91 | J11: =IF($C11="O",ROUND(ROUND(I11,2)*'Parameters '!$C$1,2),ROUND(I11,2)) -> 0 | L11: =IF($C11="O",ROUND(ROUND(K11,2)*'Parameters '!$C$1,2),ROUND(K11,2)) -> 0 | N11: =IF($C11="O",ROUND(ROUND(M11,2)*'Parameters '!$C$1,2),ROUND(M11,2)) -> 0 | P11: =IF($C11="O",ROUND(ROUND(O11,2)*'Parameters '!$C$1,2),ROUND(O11,2)) -> 0 | T11: Maintien d'actifs informationnels (MAI)
A12: System management | C12: O | G12: 5000 | H12: =IF($C12="O",ROUND(ROUND(G12,2)*'Parameters '!$C$1,2),ROUND(G12,2)) -> 5284.4 | J12: =IF($C12="O",ROUND(ROUND(I12,2)*'Parameters '!$C$1,2),ROUND(I12,2)) -> 0 | L12: =IF($C12="O",ROUND(ROUND(K12,2)*'Parameters '!$C$1,2),ROUND(K12,2)) -> 0 | N12: =IF($C12="O",ROUND(ROUND(M12,2)*'Parameters '!$C$1,2),ROUND(M12,2)) -> 0 | P12: =IF($C12="O",ROUND(ROUND(O12,2)*'Parameters '!$C$1,2),ROUND(O12,2)) -> 0 | T12: Accélération numérique (AC)
A13: Programmer | G13: 1000 | H13: =IF($C13="O",ROUND(ROUND(G13,2)*'Parameters '!$C$1,2),ROUND(G13,2)) -> 1000 | J13: =IF($C13="O",ROUND(ROUND(I13,2)*'Parameters '!$C$1,2),ROUND(I13,2)) -> 0 | L13: =IF($C13="O",ROUND(ROUND(K13,2)*'Parameters '!$C$1,2),ROUND(K13,2)) -> 0 | N13: =IF($C13="O",ROUND(ROUND(M13,2)*'Parameters '!$C$1,2),ROUND(M13,2)) -> 0 | P13: =IF($C13="O",ROUND(ROUND(O13,2)*'Parameters '!$C$1,2),ROUND(O13,2)) -> 0 | T13: Fondation - fonds d'exploitation (CAP)
A14: Budget Execution item exploit 4 | H14: =IF($C14="O",ROUND(ROUND(G14,2)*'Parameters '!$C$1,2),ROUND(G14,2)) -> 0 | J14: =IF($C14="O",ROUND(ROUND(I14,2)*'Parameters '!$C$1,2),ROUND(I14,2)) -> 0 | L14: =IF($C14="O",ROUND(ROUND(K14,2)*'Parameters '!$C$1,2),ROUND(K14,2)) -> 0 | N14: =IF($C14="O",ROUND(ROUND(M14,2)*'Parameters '!$C$1,2),ROUND(M14,2)) -> 0 | P14: =IF($C14="O",ROUND(ROUND(O14,2)*'Parameters '!$C$1,2),ROUND(O14,2)) -> 0 | T14: Fondation - fonds d'exploitation ( NON CAP)
A15: Budget Execution item exploit 5 | H15: =IF($C15="O",ROUND(ROUND(G15,2)*'Parameters '!$C$1,2),ROUND(G15,2)) -> 0 | J15: =IF($C15="O",ROUND(ROUND(I15,2)*'Parameters '!$C$1,2),ROUND(I15,2)) -> 0 | L15: =IF($C15="O",ROUND(ROUND(K15,2)*'Parameters '!$C$1,2),ROUND(K15,2)) -> 0 | N15: =IF($C15="O",ROUND(ROUND(M15,2)*'Parameters '!$C$1,2),ROUND(M15,2)) -> 0 | P15: =IF($C15="O",ROUND(ROUND(O15,2)*'Parameters '!$C$1,2),ROUND(O15,2)) -> 0 | T15: Fondation - fonds d'immobilisation (CAP)
A16: Total Operating Fund Expenditures | G16: =SUM(G11:G15) -> 6350 | H16: =SUM(H11:H15) -> 6654.31 | I16: =SUM(I11:I15) -> 0 | J16: =SUM(J11:J15) -> 0 | K16: =SUM(K11:K15) -> 0 | L16: =SUM(L11:L15) -> 0 | M16: =SUM(M11:M15) -> 0 | N16: =SUM(N11:N15) -> 0 | ... P16: =SUM(P11:P15) -> 0 | T16: Autres - Transfert MSSS -Cap
T17: Autres - Transfert MSSS - Non Cap
A18: Investments-Capital Fund | T18: CO/CDO - Transfert MSSS - Cap
A19: 12 hours for networking installation | C19: O | G19: 9000 | H19: =IF($C19="O",ROUND(ROUND(G19,2)*'Parameters '!$C$1,2),ROUND(G19,2)) -> 9511.91 | J19: =IF($C19="O",ROUND(ROUND(I19,2)*'Parameters '!$C$1,2),ROUND(I19,2)) -> 0 | L19: =IF($C19="O",ROUND(ROUND(K19,2)*'Parameters '!$C$1,2),ROUND(K19,2)) -> 0 | N19: =IF($C19="O",ROUND(ROUND(M19,2)*'Parameters '!$C$1,2),ROUND(M19,2)) -> 0 | P19: =IF($C19="O",ROUND(ROUND(O19,2)*'Parameters '!$C$1,2),ROUND(O19,2)) -> 0 | T19: CO/CDO - Transfert MSSS - Non Cap
A20: 8 hours Remote Assist training (super users) | C20: O | G20: 6000 | H20: =IF($C20="O",ROUND(ROUND(G20,2)*'Parameters '!$C$1,2),ROUND(G20,2)) -> 6341.27 | J20: =IF($C20="O",ROUND(ROUND(I20,2)*'Parameters '!$C$1,2),ROUND(I20,2)) -> 0 | L20: =IF($C20="O",ROUND(ROUND(K20,2)*'Parameters '!$C$1,2),ROUND(K20,2)) -> 0 | N20: =IF($C20="O",ROUND(ROUND(M20,2)*'Parameters '!$C$1,2),ROUND(M20,2)) -> 0 | P20: =IF($C20="O",ROUND(ROUND(O20,2)*'Parameters '!$C$1,2),ROUND(O20,2)) -> 0 | T20: Autres financés par le gouvernement fédéral (NON CAP)
A21: Total Investments-Capital Fund | G21: =SUM(G19:G20) -> 15000 | H21: =SUM(H19:H20) -> 15853.18 | I21: =SUM(I19:I20) -> 0 | J21: =SUM(J19:J20) -> 0 | K21: =SUM(K19:K20) -> 0 | L21: =SUM(L19:L20) -> 0 | M21: =SUM(M19:M20) -> 0 | N21: =SUM(N19:N20) -> 0 | ... P21: =SUM(P19:P20) -> 0 | T21: Conversion - Dépenses réelles - 2018-2019
T22: Fonds immo - PCFI - Cap
A23: Other Sources of Financing Ex: fondation, FRISSS | T23: Fonds immo - PCEM - Cap
A24: Budget Execution item other source 1 | H24: =IF($C24="O",ROUND(ROUND(G24,2)*'Parameters '!$C$1,2),ROUND(G24,2)) -> 0 | J24: =IF($C24="O",ROUND(ROUND(I24,2)*'Parameters '!$C$1,2),ROUND(I24,2)) -> 0 | L24: =IF($C24="O",ROUND(ROUND(K24,2)*'Parameters '!$C$1,2),ROUND(K24,2)) -> 0 | N24: =IF($C24="O",ROUND(ROUND(M24,2)*'Parameters '!$C$1,2),ROUND(M24,2)) -> 0 | P24: =IF($C24="O",ROUND(ROUND(O24,2)*'Parameters '!$C$1,2),ROUND(O24,2)) -> 0 | T24: Fonds immo - AC - Cap
A25: Budget Execution item other source 2 | H25: =IF($C25="O",ROUND(ROUND(G25,2)*'Parameters '!$C$1,2),ROUND(G25,2)) -> 0 | J25: =IF($C25="O",ROUND(ROUND(I25,2)*'Parameters '!$C$1,2),ROUND(I25,2)) -> 0 | L25: =IF($C25="O",ROUND(ROUND(K25,2)*'Parameters '!$C$1,2),ROUND(K25,2)) -> 0 | N25: =IF($C25="O",ROUND(ROUND(M25,2)*'Parameters '!$C$1,2),ROUND(M25,2)) -> 0 | P25: =IF($C25="O",ROUND(ROUND(O25,2)*'Parameters '!$C$1,2),ROUND(O25,2)) -> 0 | T25: Fonds immo - MAI - Cap
A26: Total other sources of funding | G26: =SUM(G24:G25) -> 0 | H26: =SUM(H24:H25) -> 0 | I26: =SUM(I24:I25) -> 0 | J26: =SUM(J24:J25) -> 0 | K26: =SUM(K24:K25) -> 0 | L26: =SUM(L24:L25) -> 0 | M26: =SUM(M24:M25) -> 0 | N26: =SUM(N24:N25) -> 0 | ... P26: =SUM(P24:P25) -> 0 | T26: Fonds immo - Courant - Cap
A27: Subtotal for the Implementation phase | G27: =G16+G21+G26 -> 21350 | H27: =H16+H21+H26 -> 22507.49 | I27: =I16+I21+I26 -> 0 | J27: =J16+J21+J26 -> 0 | K27: =K16+K21+K26 -> 0 | L27: =L16+L21+L26 -> 0 | M27: =M16+M21+M26 -> 0 | N27: =N16+N21+N26 -> 0 | ... P27: =P16+P21+P26 -> 0 | T27: Fonds exploitation - Crédits reportés - Non Cap
A28: Total cost before taxes of the Execution phase | G28: =SUM(G27,I27,K27,M27,O27) -> 21350 | T28: Fonds exploitation - Solde de fonds - Non Cap
A29: Total cost after tax for the Execution phase | G29: =SUM(H27,J27,L27,N27,P27) -> 22507.49 | T29: Fonds exploitation - Dépense de l'exercice - Non Cap
T30: Fonds exploitation - Crédits reportés - Cap
T31: Fonds exploitation - Solde de fonds - Cap
T32: Fonds exploitation - Dépense de l'exercice - Cap
T33: PMT – Transfert MSSS (NON CAP)
T34: PMT – EIRI (CAP))

Sheet Monitoring execution budget  
A1: Monitors the Budget over the course of one year.*** | F1: Flag a problem | G1: Cost with Tax
A2: Would need the option to have it 1 to 7 years***
A6: Initial amount: | B6: ='Budget Execution'!G27 -> 21350
A7: Invoiced amount | B7: =D19+D28+D37+D46+D55+D66+D75+D84+D93+D102+D111+D120+D129+D138+D147+D158+D167+D176+D185+D194 -> 17130
A8: Balance: | B8: =B6-B7 -> 4220
A10: BUDGET Execution
A11: Operating fund expenditures
A12: ='Budget Execution'!A11 -> Project management
A13: Date trans. | B13: Description | C13: Budgeted amount | D13: Transaction | E13: Balance:
B14: Montant 2023-2024 | C14: ='Budget Execution'!G11 -> 350
D15: 150
A19: Balance: | C19: =SUM(C14:C18) -> 350 | D19: =SUM(D14:D18) -> 150 | E19: =C19-D19 -> 200
A21: ='Budget Execution'!A12 -> System management
A22: Date trans. | B22: Description | C22: Budgeted amount | D22: Transaction | E22: Balance:
B23: Montant 2023-2024 | C23: ='Budget Execution'!G12 -> 5000
D24: 4980
A28: Balance: | C28: =SUM(C23:C27) -> 5000 | D28: =SUM(D23:D27) -> 4980 | E28: =C28-D28 -> 20
A30: ='Budget Execution'!A13 -> Programmer
A31: Date trans. | B31: Description | C31: Budgeted amount | D31: Transaction | E31: Balance:
B32: Montant 2023-2024 | C32: ='Budget Execution'!G13 -> 1000
D33: 1000
A37: Balance: | C37: =SUM(C32:C36) -> 1000 | D37: =SUM(D32:D36) -> 1000 | E37: =C37-D37 -> 0
A39: ='Budget Execution'!A14 -> Budget Execution item exploit 4
A40: Date trans. | B40: Description | C40: Budgeted amount | D40: Transaction | E40: Balance:
B41: Montant 2023-2024 | C41: ='Budget Execution'!G14 -> 0
A46: Balance: | C46: =SUM(C41:C45) -> 0 | D46: =SUM(D41:D45) -> 0 | E46: =C46-D46 -> 0
A48: ='Budget Execution'!A15 -> Budget Execution item exploit 5
A49: Date trans. | B49: Description | C49: Budgeted amount | D49: Transaction | E49: Balance:
B50: Montant 2023-2024 | C50: ='Budget Execution'!G15 -> 0
A55: Balance: | C55: =SUM(C50:C54) -> 0 | D55: =SUM(D50:D54) -> 0 | E55: =C55-D55 -> 0
A57: Budget Execution
A58: Expenditures - capital fund
A59: ='Budget Execution'!A19 -> 12 hours for networking installation | D59: 100172-9300000
A60: Date trans. | B60: Description | C60: Budgeted amount | D60: Transaction | E60: Balance:
B61: Montant 2023-2024 | C61: ='Budget Execution'!G19 -> 9000
B62: Facture 12164-36h | D62: 5000 | G62: =D62*'Parameters '!C1 -> 5284.395
G63: =D63*'Parameters '!C1 -> 0
A66: Balance: | C66: =SUM(C61:C65) -> 9000 | D66: =SUM(D61:D65) -> 5000 | E66: =C66-D66 -> 4000
A68: ='Budget Execution'!A20 -> 8 hours Remote Assist training (super users) | D68: 100172-9300000
A69: Date trans. | B69: Description | C69: Budgeted amount | D69: Transaction | E69: Balance:
...
